<?xml version="1.0" ?>
<!-- =================================================================================== -->
<!-- |    This document was autogenerated by xacro from /home/xinhongwang/ws02_tools/install/cpp06_urdf/share/cpp06_urdf/urdf/xacro/car.urdf.xacro | -->
<!-- |    EDITING THIS FILE BY HAND IS NOT RECOMMENDED                                 | -->
<!-- =================================================================================== -->
<robot name="car">
  <material name="yellow">
    <color rgba="0.9 0.6 0.0 0.5"/>
  </material>
  <material name="black">
    <color rgba="0.0 0.0 0.0 0.5"/>
  </material>
  <!-- 2.设置base_footprint -->
  <link name="base_footprint">
    <visual>
      <geometry>
        <sphere radius="0.001"/>
      </geometry>
    </visual>
  </link>
  <!-- 3.设置base_link -->
  <link name="base_link">
    <visual>
      <geometry>
        <box size="0.2 0.12 0.07"/>
      </geometry>
      <material name="yellow"/>
    </visual>
    <collision>
      <geometry>
        <box size="0.2 0.12 0.07"/>
      </geometry>
      <material name="yellow"/>
    </collision>
  </link>
  <!-- 4.使用joint将二者相联 -->
  <joint name="base_link2base_footprint" type="fixed">
    <parent link="base_footprint"/>
    <child link="base_link"/>
    <origin xyz="0.0 0.0 0.05"/>
  </joint>
  <link name="front_left">
    <visual>
      <geometry>
        <cylinder length="0.02" radius="0.025"/>
      </geometry>
      <material name="black"/>
      <origin rpy="1.57079635 0.0 0.0"/>
    </visual>
    <collision>
      <geometry>
        <cylinder length="0.02" radius="0.025"/>
      </geometry>
      <material name="black"/>
      <origin rpy="1.57079635 0.0 0.0"/>
    </collision>
  </link>
  <joint name="front_left2base_link" type="continuous">
    <parent link="base_link"/>
    <child link="front_left"/>
    <origin xyz="0.08 0.06 -0.025"/>
    <axis xyz="0 1 0"/>
  </joint>
  <link name="front_right">
    <visual>
      <geometry>
        <cylinder length="0.02" radius="0.025"/>
      </geometry>
      <material name="black"/>
      <origin rpy="1.57079635 0.0 0.0"/>
    </visual>
    <collision>
      <geometry>
        <cylinder length="0.02" radius="0.025"/>
      </geometry>
      <material name="black"/>
      <origin rpy="1.57079635 0.0 0.0"/>
    </collision>
  </link>
  <joint name="front_right2base_link" type="continuous">
    <parent link="base_link"/>
    <child link="front_right"/>
    <origin xyz="0.08 -0.06 -0.025"/>
    <axis xyz="0 1 0"/>
  </joint>
  <link name="back_left">
    <visual>
      <geometry>
        <cylinder length="0.02" radius="0.025"/>
      </geometry>
      <material name="black"/>
      <origin rpy="1.57079635 0.0 0.0"/>
    </visual>
    <collision>
      <geometry>
        <cylinder length="0.02" radius="0.025"/>
      </geometry>
      <material name="black"/>
      <origin rpy="1.57079635 0.0 0.0"/>
    </collision>
  </link>
  <joint name="back_left2base_link" type="continuous">
    <parent link="base_link"/>
    <child link="back_left"/>
    <origin xyz="-0.08 0.06 -0.025"/>
    <axis xyz="0 1 0"/>
  </joint>
  <link name="back_right">
    <visual>
      <geometry>
        <cylinder length="0.02" radius="0.025"/>
      </geometry>
      <material name="black"/>
      <origin rpy="1.57079635 0.0 0.0"/>
    </visual>
    <collision>
      <geometry>
        <cylinder length="0.02" radius="0.025"/>
      </geometry>
      <material name="black"/>
      <origin rpy="1.57079635 0.0 0.0"/>
    </collision>
  </link>
  <joint name="back_right2base_link" type="continuous">
    <parent link="base_link"/>
    <child link="back_right"/>
    <origin xyz="-0.08 -0.06 -0.025"/>
    <axis xyz="0 1 0"/>
  </joint>
  <!-- 设置link和joint -->
  <link name="camera">
    <visual>
      <geometry>
        <box size="0.01 0.08 0.01"/>
      </geometry>
    </visual>
    <collision>
      <geometry>
        <box size="0.01 0.08 0.01"/>
      </geometry>
    </collision>
  </link>
  <joint name="camera2base_link" type="fixed">
    <parent link="base_link"/>
    <child link="camera"/>
    <origin xyz="0.09000000000000001 0 0.04 "/>
  </joint>
  <!-- 设置link和joint -->
  <link name="laser">
    <visual>
      <geometry>
        <cylinder length="0.03" radius="0.03"/>
      </geometry>
      <material name="blue">
        <color rgba="0.1 0.1 0.7 0.8"/>
      </material>
    </visual>
    <collision>
      <geometry>
        <cylinder length="0.03" radius="0.03"/>
      </geometry>
      <material name="blue">
        <color rgba="0.1 0.1 0.7 0.8"/>
      </material>
    </collision>
  </link>
  <joint name="laser2base_link" type="fixed">
    <parent link="base_link"/>
    <child link="laser"/>
    <origin xyz="0 0 0.05"/>
  </joint>
</robot>
